Workbook

Sheet Ringkasan
A1: Test Plan – E2E Test Automation Website BAZNAS (baznas.go.id)
A3: Aplikasi yang diuji | B3: Website publik BAZNAS RI – https://baznas.go.id (termasuk form pembayaran di https://bayarzakat.baznas.go.id)
A4: Tools | B4: Cypress (TypeScript), Page Object Model, Mochawesome report, cypress-axe, @cypress/grep, GitHub Actions
A5: Lingkungan | B5: Production (publik). Browser: Chrome (utama), Edge, Firefox. Viewport: desktop 1440x900, tablet 768x1024, mobile 375x812
A6: Disusun oleh | B6: Revan – QA Automation Engineer
A7: Repository | B7: baznas-web-e2e (Cypress) – kolom Spec File menunjuk ke file test terkait
A8: Tanggal eksplorasi | B8: 27 Oktober 2026
A9: Versi dokumen | B9: v1.0
A11: Tujuan
B12: • Menyediakan regression test otomatis untuk halaman publik, navigasi, konten, kalkulator zakat dan alur form pembayaran ZIS.
B13: • Mendeteksi lebih awal broken link, perubahan konten penting (rekening, nisab, tarif fidyah) dan regresi fungsi setelah deployment.
B14: • Dijalankan terjadwal (harian) melalui CI sebagai monitoring kualitas website.
A16: Dalam cakupan
B17: • Fungsional UI: homepage, menu, bottom nav, footer, multi-bahasa, halaman konten & laporan.
B18: • Logika bisnis: kalkulator zakat (nisab & 2,5%), perhitungan fidyah otomatis.
B19: • Validasi form (negative test) pada form bayar zakat, jemput zakat dan newsletter – tanpa mengirim data.
B20: • Non-fungsional ringan: broken link, SEO metadata, aksesibilitas dasar, waktu muat, responsive.
A22: Di luar cakupan
B23: • Transaksi pembayaran nyata – alur berhenti sebelum metode pembayaran diproses; request transaksi diblokir dengan cy.intercept().
B24: • Submit form yang menyimpan data ke server (jemput zakat, newsletter, konfirmasi) dan penyelesaian captcha.
B25: • Load / stress / security testing.
B26: • Konten & fungsi situs pihak ketiga (PPID, bazn.as, media sosial) – hanya dicek ketersediaan link-nya.
A28: Strategi & aturan eksekusi
B29: • Data uji memakai data dummy di folder fixtures; tidak memakai data pribadi asli.
B30: • Nilai yang bisa berubah (nisab, tarif fidyah, daftar rekening, metode pembayaran) disimpan di fixture agar mudah diperbarui.
B31: • Domain bayarzakat.baznas.go.id diuji dengan cy.origin() (cross-origin).
B32: • Frekuensi eksekusi dibatasi (on-push & 1x sehari) dan request link-check diberi jeda agar tidak membebani server.
B33: • Tag: @smoke (cek cepat), @regression (lengkap), @a11y, @perf – dijalankan selektif dengan @cypress/grep.
A35: Ringkasan jumlah
A36: Total modul | B36: =COUNTA('Modul & Cakupan'!A:A)-1
A37: Total test scenario | B37: =COUNTA('Test Scenario'!A:A)-1
A38: Total test case | B38: =COUNTA('Test Case'!A:A)-1
A39: Prioritas P1 | B39: =COUNTIF('Test Case'!I:I,"P1")
A40: Prioritas P2 | B40: =COUNTIF('Test Case'!I:I,"P2")
A41: Prioritas P3 | B41: =COUNTIF('Test Case'!I:I,"P3")
A42: Positive | B42: =COUNTIF('Test Case'!H:H,"Positive")
A43: Negative | B43: =COUNTIF('Test Case'!H:H,"Negative")
A44: Boundary | B44: =COUNTIF('Test Case'!H:H,"Boundary")
A45: Tag @smoke | B45: =COUNTIF('Test Case'!J:J,"*@smoke*")
A46: Tag @known-bug | B46: =COUNTIF('Test Case'!J:J,"*@known-bug*")
...

Sheet Modul & Cakupan
A1: Kode | B1: Modul | C1: Halaman / Area | D1: Spec File | E1: Jml Scenario | F1: Jml Test Case
A2: HOME | B2: Homepage | C2: / | D2: cypress/e2e/home.cy.ts | E2: =COUNTIF('Test Scenario'!B:B,A2) | F2: =COUNTIF('Test Case'!C:C,A2)
A3: NAV | B3: Header & Menu Navigasi | C3: Header, menu hamburger | D3: cypress/e2e/navigation.cy.ts | E3: =COUNTIF('Test Scenario'!B:B,A3) | F3: =COUNTIF('Test Case'!C:C,A3)
A4: BNAV | B4: Bottom Navigation (Quick Menu) | C4: Bar bawah: PPID, Layanan Mustahik, Bayar Zakat, Konfirmasi, Transfer Zakat | D4: cypress/e2e/bottom-nav.cy.ts | E4: =COUNTIF('Test Scenario'!B:B,A4) | F4: =COUNTIF('Test Case'!C:C,A4)
A5: FTR | B5: Footer | C5: Footer seluruh halaman | D5: cypress/e2e/footer.cy.ts | E5: =COUNTIF('Test Scenario'!B:B,A5) | F5: =COUNTIF('Test Case'!C:C,A5)
A6: I18N | B6: Multi-bahasa | C6: Language switcher ID / EN / AR | D6: cypress/e2e/i18n.cy.ts | E6: =COUNTIF('Test Scenario'!B:B,A6) | F6: =COUNTIF('Test Case'!C:C,A6)
A7: CALC | B7: Kalkulator Zakat | C7: /kalkulatorzakat | D7: cypress/e2e/kalkulator-zakat.cy.ts | E7: =COUNTIF('Test Scenario'!B:B,A7) | F7: =COUNTIF('Test Case'!C:C,A7)
A8: PAY | B8: Form Bayar Zakat Online | C8: /bayarzakat -> bayarzakat.baznas.go.id | D8: cypress/e2e/bayar-zakat.cy.ts | E8: =COUNTIF('Test Scenario'!B:B,A8) | F8: =COUNTIF('Test Case'!C:C,A8)
A9: JMP | B9: Form Jemput Zakat | C9: /form-jemput-zakat | D9: cypress/e2e/jemput-zakat.cy.ts | E9: =COUNTIF('Test Scenario'!B:B,A9) | F9: =COUNTIF('Test Case'!C:C,A9)
A10: KONF | B10: Konfirmasi ZIS | C10: /konfirmasi-zis | D10: cypress/e2e/konfirmasi-zis.cy.ts | E10: =COUNTIF('Test Scenario'!B:B,A10) | F10: =COUNTIF('Test Case'!C:C,A10)
A11: REK | B11: Rekening Zakat | C11: /rekening | D11: cypress/e2e/rekening.cy.ts | E11: =COUNTIF('Test Scenario'!B:B,A11) | F11: =COUNTIF('Test Case'!C:C,A11)
A12: EDU | B12: Konten Edukasi ZIS | C12: /zakat, /infak, /sedekah, /fidyah, /zakatfitrah, /zakatmal, dst. | D12: cypress/e2e/edukasi-zis.cy.ts | E12: =COUNTIF('Test Scenario'!B:B,A12) | F12: =COUNTIF('Test Case'!C:C,A12)
A13: NEWS | B13: Berita & Publikasi | C13: /news-all, /berita-pendistribusian, /artikel-all, /berkah-zakat-all, /video-all | D13: cypress/e2e/berita.cy.ts | E13: =COUNTIF('Test Scenario'!B:B,A13) | F13: =COUNTIF('Test Case'!C:C,A13)
... A23: PERF | B23: Performa Dasar | C23: Waktu muat halaman utama | D23: cypress/e2e/performance.cy.ts | E23: =COUNTIF('Test Scenario'!B:B,A23) | F23: =COUNTIF('Test Case'!C:C,A23)

Sheet Test Scenario
A1: Scenario ID | B1: Kode Modul | C1: Modul | D1: Test Scenario | E1: Jenis Pengujian | F1: Prioritas | G1: Jml Test Case
A2: TS-HOME-01 | B2: HOME | C2: Homepage | D2: Memastikan homepage dapat diakses dan elemen utama tampil | E2: Functional / Smoke | F2: P1 | G2: =COUNTIF('Test Case'!B:B,A2)
A3: TS-HOME-02 | B3: HOME | C3: Homepage | D3: Memastikan kartu Zakat, Infak, Sedekah, Fidyah berfungsi | E3: Functional | F3: P1 | G3: =COUNTIF('Test Case'!B:B,A3)
A4: TS-HOME-03 | B4: HOME | C4: Homepage | D4: Memastikan banner/slider dan section berita di homepage berfungsi | E4: Functional / UI | F4: P2 | G4: =COUNTIF('Test Case'!B:B,A4)
A5: TS-NAV-01 | B5: NAV | C5: Header & Menu Navigasi | D5: Memastikan menu hamburger dapat dibuka/ditutup | E5: Functional / Smoke | F5: P1 | G5: =COUNTIF('Test Case'!B:B,A5)
A6: TS-NAV-02 | B6: NAV | C6: Header & Menu Navigasi | D6: Memastikan setiap item & sub-menu mengarah ke halaman yang benar | E6: Functional | F6: P1 | G6: =COUNTIF('Test Case'!B:B,A6)
A7: TS-BNAV-01 | B7: BNAV | C7: Bottom Navigation (Quick Menu) | D7: Memastikan quick menu bawah tampil & mengarah ke tujuan yang benar | E7: Functional / Smoke | F7: P1 | G7: =COUNTIF('Test Case'!B:B,A7)
A8: TS-FTR-01 | B8: FTR | C8: Footer | D8: Memastikan link footer & media sosial valid | E8: Functional | F8: P2 | G8: =COUNTIF('Test Case'!B:B,A8)
A9: TS-I18N-01 | B9: I18N | C9: Multi-bahasa | D9: Memastikan pergantian bahasa ID / EN / AR berfungsi | E9: Functional / UI | F9: P2 | G9: =COUNTIF('Test Case'!B:B,A9)
A10: TS-CALC-01 | B10: CALC | C10: Kalkulator Zakat | D10: Menghitung zakat penghasilan sesuai nisab & tarif 2,5% | E10: Functional / Business Logic | F10: P1 | G10: =COUNTIF('Test Case'!B:B,A10)
A11: TS-CALC-02 | B11: CALC | C11: Kalkulator Zakat | D11: Validasi input kalkulator (kosong, non-angka, nol, negatif) | E11: Negative | F11: P1 | G11: =COUNTIF('Test Case'!B:B,A11)
A12: TS-CALC-03 | B12: CALC | C12: Kalkulator Zakat | D12: Fungsi tombol Reset, Hitung, Bayar Zakat dan Sedekah | E12: Functional | F12: P1 | G12: =COUNTIF('Test Case'!B:B,A12)
A13: TS-CALC-04 | B13: CALC | C13: Kalkulator Zakat | D13: Kalkulator jenis Perusahaan, Perdagangan dan Emas | E13: Functional / Business Logic | F13: P2 | G13: =COUNTIF('Test Case'!B:B,A13)
... A35: TS-PERF-01 | B35: PERF | C35: Performa Dasar | D35: Waktu muat halaman utama dalam batas wajar | E35: Non-functional | F35: P3 | G35: =COUNTIF('Test Case'!B:B,A35)

Sheet Test Case
A1: TC ID | B1: Scenario ID | C1: Modul | D1: Judul Test Case | E1: Pre-condition | F1: Langkah Pengujian | G1: Test Data | H1: Tipe | I1: Prioritas | J1: Tag | K1: Automation | L1: Expected Result | M1: Status | N1: Catatan | O1: Spec File | P1: Fase Otomasi
A2: TC-HOME-001 | B2: TS-HOME-01 | C2: HOME | D2: Homepage berhasil dimuat | E2: Browser terbuka, koneksi internet aktif | F2: 1. Buka https://baznas.go.id/ | G2: - | H2: Positive | I2: P1 | J2: @smoke | K2: Automated | L2: Status HTTP 200, halaman tampil tanpa error, title mengandung 'BAZNAS' | M2: Not Run | O2: cypress/e2e/home.cy.ts | P2: Fase 1
A3: TC-HOME-002 | B3: TS-HOME-01 | C3: HOME | D3: Logo BAZNAS tampil dan mengarah ke beranda | E3: Browser terbuka, koneksi internet aktif | F3: 1. Buka halaman mana pun (mis. /zakat) 2. Klik logo BAZNAS di header | G3: - | H3: Positive | I3: P1 | J3: @smoke | K3: Automated | L3: Logo tampil (gambar ter-load, naturalWidth > 0); klik logo membuka https://baznas.go.id/ | M3: Not Run | O3: cypress/e2e/home.cy.ts | P3: Fase 1
A4: TC-HOME-003 | B4: TS-HOME-01 | C4: HOME | D4: Tidak ada error JavaScript saat homepage dimuat | E4: Browser terbuka, koneksi internet aktif | F4: 1. Buka homepage 2. Pantau uncaught exception di console | G4: - | H4: Positive | I4: P2 | J4: @regression | K4: Automated | L4: Tidak ada uncaught exception yang menggagalkan render halaman | M4: Not Run | N4: Gunakan Cypress.on('uncaught:exception') untuk mencatat | O4: cypress/e2e/home.cy.ts | P4: Fase 2
A5: TC-HOME-004 | B5: TS-HOME-02 | C5: HOME | D5: Kartu Zakat, Infak, Sedekah, Fidyah tampil | E5: Browser terbuka, koneksi internet aktif | F5: 1. Buka homepage 2. Scroll ke section kartu ZIS | G5: - | H5: Positive | I5: P1 | J5: @smoke | K5: Automated | L5: 4 kartu tampil, masing-masing berisi ikon, judul dan ringkasan definisi | M5: Not Run | O5: cypress/e2e/home.cy.ts | P5: Fase 1
A6: TC-HOME-005 | B6: TS-HOME-02 | C6: HOME | D6: Tombol 'Selengkapnya' di setiap kartu mengarah ke halaman yang benar | E6: Browser terbuka, koneksi internet aktif | F6: 1. Buka homepage 2. Klik 'Selengkapnya' pada kartu Zakat / Infak / Sedekah / Fidyah | G6: Zakat -> /zakat Infak -> /infak Sedekah -> /sedekah Fidyah -> /fidyah | H6: Positive | I6: P1 | J6: @regression | K6: Automated | L6: Setiap tombol membuka URL sesuai dengan status 200 dan judul halaman sesuai | M6: Not Run | N6: Data-driven dari fixture | O6: cypress/e2e/home.cy.ts | P6: Fase 1
A7: TC-HOME-006 | B7: TS-HOME-03 | C7: HOME | D7: Banner/slider utama tampil dan dapat berganti | E7: Browser terbuka, koneksi internet aktif | F7: 1. Buka homepage 2. Amati banner utama beberapa detik / klik navigasi slider | G7: - | H7: Positive | I7: P2 | J7: @regression | K7: Partial | L7: Banner tampil, gambar ter-load, slide berganti tanpa error | M7: Not Run | N7: Konten banner dinamis; asersi pada keberadaan & gambar ter-load, bukan isi | O7: cypress/e2e/home.cy.ts | P7: Fase 2
A8: TC-HOME-007 | B8: TS-HOME-03 | C8: HOME | D8: Section 'Berita Program' menampilkan daftar berita terbaru | E8: Browser terbuka, koneksi internet aktif | F8: 1. Buka homepage 2. Scroll ke section 'Berita Program' | G8: - | H8: Positive | I8: P2 | J8: @regression | K8: Automated | L8: Minimal 1 berita tampil dengan judul, tanggal (dd/mm/yyyy) dan penulis | M8: Not Run | O8: cypress/e2e/home.cy.ts | P8: Fase 2
A9: TC-HOME-008 | B9: TS-HOME-03 | C9: HOME | D9: Tombol 'Load more' di section berita mengarah ke halaman daftar | E9: Browser terbuka, koneksi internet aktif | F9: 1. Buka homepage 2. Klik 'Load more' pada masing-masing section | G9: Berita -> /news-all Pendistribusian -> /berita-pendistribusian Berkah Zakat -> /berkah-zakat-all Video -> /video-all | H9: Positive | I9: P2 | J9: @regression | K9: Automated | L9: Setiap tombol membuka halaman daftar yang sesuai (status 200) | M9: Not Run | O9: cypress/e2e/home.cy.ts | P9: Fase 2
A10: TC-HOME-009 | B10: TS-HOME-03 | C10: HOME | D10: Klik salah satu berita di homepage membuka detail berita | E10: Browser terbuka, koneksi internet aktif | F10: 1. Buka homepage 2. Klik judul berita pertama | G10: - | H10: Positive | I10: P2 | J10: @regression | K10: Automated | L10: Halaman detail terbuka, judul pada detail sama dengan judul di kartu (abaikan '...' terpotong) | M10: Not Run | O10: cypress/e2e/home.cy.ts | P10: Fase 2
A11: TC-NAV-001 | B11: TS-NAV-01 | C11: NAV | D11: Menu hamburger dapat dibuka dan ditutup | E11: Browser terbuka, koneksi internet aktif | F11: 1. Buka homepage 2. Klik ikon hamburger 3. Klik ikon lagi / area luar | G11: - | H11: Positive | I11: P1 | J11: @smoke | K11: Automated | L11: Menu samping tampil berisi: Beranda, Tentang BAZNAS, Profil Program, Panduan Brand, Zakat, Layanan, Kabar, Laporan, PPID, Pustaka, BAZNAS Daerah, Jaringan; menu tertutup kembali | M11: Not Run | O11: cypress/e2e/navigation.cy.ts | P11: Fase 1
A12: TC-NAV-002 | B12: TS-NAV-01 | C12: NAV | D12: Sub-menu dapat di-expand | E12: Browser terbuka, koneksi internet aktif | F12: 1. Buka menu hamburger 2. Klik item yang memiliki panah (Tentang BAZNAS, Zakat, Layanan, Kabar, Laporan, dll.) | G12: - | H12: Positive | I12: P1 | J12: @regression | K12: Automated | L12: Sub-menu terbuka dan menampilkan item turunan | M12: Not Run | O12: cypress/e2e/navigation.cy.ts | P12: Fase 1
A13: TC-NAV-003 | B13: TS-NAV-02 | C13: NAV | D13: Sub-menu Tentang BAZNAS mengarah ke halaman benar | E13: Menu hamburger terbuka | F13: 1. Expand 'Tentang BAZNAS' 2. Klik setiap sub-menu | G13: Profil -> /baznas-profile Struktur -> /struktur-baznas Penghargaan -> /penghargaan Mitra -> /mitra-baznas Pemberitahuan -> /pemberitahuan Karir -> /karir | H13: Positive | I13: P1 | J13: @regression | K13: Automated | L13: Setiap halaman terbuka dengan status 200 dan heading sesuai | M13: Not Run | N13: Data-driven | O13: cypress/e2e/navigation.cy.ts | P13: Fase 1
A14: TC-NAV-004 | B14: TS-NAV-02 | C14: NAV | D14: Sub-menu Zakat mengarah ke halaman benar | E14: Menu hamburger terbuka | F14: 1. Expand 'Zakat' 2. Klik setiap sub-menu | G14: Zakat Fitrah, Zakat Mal, Penghasilan, Perusahaan, Perdagangan, Emas, Saham | H14: Positive | I14: P1 | J14: @regression | K14: Automated | L14: Setiap halaman terbuka dengan status 200 | M14: Not Run | N14: Data-driven | O14: cypress/e2e/navigation.cy.ts | P14: Fase 1
A15: TC-NAV-005 | B15: TS-NAV-02 | C15: NAV | D15: Sub-menu Layanan mengarah ke halaman benar | E15: Menu hamburger terbuka | F15: 1. Expand 'Layanan' 2. Klik setiap sub-menu | G15: UPZ, Zakat Karyawan, Register Label Taat Zakat, Konfirmasi ZIS, Kurban Online, Kalkulator Zakat, Layanan Pembayaran, Jemput Zakat, Layanan Rekomendasi | H15: Positive | I15: P1 | J15: @regression | K15: Automated | L15: Setiap halaman terbuka (status 200); link eksternal (bazn.as, ppid) merespons 2xx/3xx | M15: Not Run | O15: cypress/e2e/navigation.cy.ts | P15: Fase 1
A16: TC-NAV-006 | B16: TS-NAV-02 | C16: NAV | D16: Sub-menu Profil Program, Kabar, Laporan, Jaringan mengarah ke halaman benar | E16: Menu hamburger terbuka | F16: 1. Expand setiap menu 2. Klik setiap sub-menu | G16: Lihat fixture menu.json | H16: Positive | I16: P2 | J16: @regression | K16: Automated | L16: Setiap halaman terbuka dengan status 200 | M16: Not Run | O16: cypress/e2e/navigation.cy.ts | P16: Fase 2
A17: TC-BNAV-001 | B17: TS-BNAV-01 | C17: BNAV | D17: Quick menu bawah tampil di semua halaman utama | E17: Browser terbuka, koneksi internet aktif | F17: 1. Buka homepage, /zakat, /kalkulatorzakat 2. Periksa bar bawah | G17: - | H17: Positive | I17: P1 | J17: @smoke | K17: Automated | L17: 5 item tampil: PPID, Layanan Mustahik, Bayar Zakat, Konfirmasi Zakat, Transfer Zakat | M17: Not Run | O17: cypress/e2e/bottom-nav.cy.ts | P17: Fase 1
A18: TC-BNAV-002 | B18: TS-BNAV-01 | C18: BNAV | D18: Tombol 'Bayar Zakat' membuka form pembayaran | E18: Browser terbuka, koneksi internet aktif | F18: 1. Klik tombol 'Bayar Zakat' (ikon tengah) | G18: - | H18: Positive | I18: P1 | J18: @smoke | K18: Automated | L18: Diarahkan ke /bayarzakat (redirect ke bayarzakat.baznas.go.id) dan form tampil | M18: Not Run | N18: Cross-origin: gunakan cy.origin() | O18: cypress/e2e/bottom-nav.cy.ts | P18: Fase 1
A19: TC-BNAV-003 | B19: TS-BNAV-01 | C19: BNAV | D19: Item PPID, Layanan Mustahik, Konfirmasi, Transfer mengarah ke tujuan benar | E19: Browser terbuka, koneksi internet aktif | F19: 1. Periksa href setiap item 2. Request setiap URL | G19: PPID -> ppid.baznas.go.id Layanan Mustahik -> bazn.as/LayananMustahik Konfirmasi -> /konfirmasi-zis Transfer -> /rekening | H19: Positive | I19: P1 | J19: @regression | K19: Automated | L19: href sesuai dan URL merespons 2xx/3xx | M19: Not Run | O19: cypress/e2e/bottom-nav.cy.ts | P19: Fase 1
A20: TC-FTR-001 | B20: TS-FTR-01 | C20: FTR | D20: Link Kebijakan Privasi, Syarat & Ketentuan, FAQ berfungsi | E20: Browser terbuka, koneksi internet aktif | F20: 1. Scroll ke footer 2. Klik masing-masing link | G20: /kebijakan-privasi, /syarat-ketentuan, /faq-baznas | H20: Positive | I20: P2 | J20: @regression | K20: Automated | L20: Halaman terbuka (status 200) dan berisi konten | M20: Not Run | O20: cypress/e2e/footer.cy.ts | P20: Fase 2
A21: TC-FTR-002 | B21: TS-FTR-01 | C21: FTR | D21: Ikon media sosial mengarah ke akun resmi BAZNAS | E21: Browser terbuka, koneksi internet aktif | F21: 1. Scroll ke footer 2. Periksa href ikon sosial media | G21: Facebook, Instagram, X/Twitter, LinkedIn, YouTube, TikTok | H21: Positive | I21: P2 | J21: @regression | K21: Automated | L21: href mengarah ke akun resmi dan memiliki target='_blank' | M21: Not Run | N21: Cek href saja, tidak membuka situs pihak ketiga | O21: cypress/e2e/footer.cy.ts | P21: Fase 2
A22: TC-FTR-003 | B22: TS-FTR-01 | C22: FTR | D22: Teks copyright menampilkan tahun berjalan | E22: Browser terbuka, koneksi internet aktif | F22: 1. Scroll ke footer | G22: - | H22: Positive | I22: P3 | J22: @regression | K22: Automated | L22: Teks 'Copyright © {tahun berjalan} BAZNAS' tampil | M22: Not Run | O22: cypress/e2e/footer.cy.ts | P22: Fase 2
A23: TC-I18N-001 | B23: TS-I18N-01 | C23: I18N | D23: Dropdown bahasa berisi 3 pilihan | E23: Browser terbuka, koneksi internet aktif | F23: 1. Buka homepage 2. Periksa dropdown bahasa | G23: - | H23: Positive | I23: P2 | J23: @regression | K23: Automated | L23: Opsi: Indonesia (default terpilih), English, العربية | M23: Not Run | O23: cypress/e2e/i18n.cy.ts | P23: Fase 2
A24: TC-I18N-002 | B24: TS-I18N-01 | C24: I18N | D24: Ganti bahasa ke English | E24: Browser terbuka, koneksi internet aktif | F24: 1. Pilih 'English' pada dropdown bahasa 2. Tunggu halaman diterjemahkan | G24: - | H24: Positive | I24: P2 | J24: @regression | K24: Partial | L24: Konten utama berubah ke Bahasa Inggris (mis. 'Selengkapnya' -> 'Read more'), pilihan bahasa tetap 'English' | M24: Not Run | N24: Lihat temuan F-06; menggunakan Google Translate widget | O24: cypress/e2e/i18n.cy.ts | P24: Fase 2
A25: TC-I18N-003 | B25: TS-I18N-01 | C25: I18N | D25: Ganti bahasa ke Arab dan cek arah teks | E25: Browser terbuka, koneksi internet aktif | F25: 1. Pilih 'العربية' | G25: - | H25: Positive | I25: P3 | J25: @regression | K25: Partial | L25: Konten diterjemahkan ke Bahasa Arab; layout tidak rusak (idealnya dir='rtl') | M25: Not Run | O25: cypress/e2e/i18n.cy.ts | P25: Fase 2
A26: TC-I18N-004 | B26: TS-I18N-01 | C26: I18N | D26: Pilihan bahasa tetap saat pindah halaman | E26: Bahasa diset ke English | F26: 1. Klik menu menuju /zakat | G26: - | H26: Positive | I26: P3 | J26: @regression | K26: Partial | L26: Halaman /zakat tetap tampil dalam Bahasa Inggris | M26: Not Run | O26: cypress/e2e/i18n.cy.ts | P26: Fase 2
A27: TC-CALC-001 | B27: TS-CALC-01 | C27: CALC | D27: Nilai nisab tampil sesuai ketetapan | E27: Buka /kalkulatorzakat | F27: 1. Pilih Jenis Zakat PENGHASILAN 2. Periksa field Nisab per tahun & per bulan | G27: - | H27: Positive | I27: P1 | J27: @smoke | K27: Automated | L27: Nisab per tahun = Rp 91.681.728; Nisab per bulan = Rp 7.640.114; field read-only; keterangan 'Sesuai SK Ketua BAZNAS No. 15 tahun 2026' tampil | M27: Not Run | N27: Nilai nisab disimpan di fixture agar mudah diperbarui saat SK berubah | O27: cypress/e2e/kalkulator-zakat.cy.ts | P27: Fase 1
A28: TC-CALC-002 | B28: TS-CALC-01 | C28: CALC | D28: Jumlah penghasilan = gaji + penghasilan lain | E28: Buka https://baznas.go.id/kalkulatorzakat, Jenis Zakat = PENGHASILAN | F28: 1. Isi Gaji per bulan 2. Isi Penghasilan lain-lain | G28: Gaji = 8.000.000 Lain-lain = 2.000.000 | H28: Positive | I28: P1 | J28: @regression | K28: Automated | L28: Jumlah penghasilan per bulan = 10.000.000 (format ribuan dengan titik) | M28: Not Run | O28: cypress/e2e/kalkulator-zakat.cy.ts | P28: Fase 1
A29: TC-CALC-003 | B29: TS-CALC-01 | C29: CALC | D29: Penghasilan di atas nisab menghasilkan zakat 2,5% | E29: Buka https://baznas.go.id/kalkulatorzakat, Jenis Zakat = PENGHASILAN | F29: 1. Isi Gaji 2. Klik 'Hitung Zakat' | G29: Gaji = 10.000.000 Lain-lain = 0 | H29: Positive | I29: P1 | J29: @smoke | K29: Automated | L29: Jumlah Wajib Zakat = Rp 250.000; tombol 'Bayar Zakat' tampil | M29: Not Run | N29: Terverifikasi saat eksplorasi | O29: cypress/e2e/kalkulator-zakat.cy.ts | P29: Fase 1
A30: TC-CALC-004 | B30: TS-CALC-01 | C30: CALC | D30: Penghasilan di bawah nisab tidak wajib zakat | E30: Buka https://baznas.go.id/kalkulatorzakat, Jenis Zakat = PENGHASILAN | F30: 1. Isi Gaji 2. Klik 'Hitung Zakat' | G30: Gaji = 5.000.000 | H30: Positive | I30: P1 | J30: @regression | K30: Automated | L30: Muncul pesan 'Penghasilan Anda belum mencapai Nisab, KLIK untuk sedekah' dan tombol 'Sedekah'; zakat = 0 | M30: Not Run | N30: Terverifikasi saat eksplorasi | O30: cypress/e2e/kalkulator-zakat.cy.ts | P30: Fase 1
A31: TC-CALC-005 | B31: TS-CALC-01 | C31: CALC | D31: Boundary: penghasilan tepat sama dengan nisab | E31: Buka https://baznas.go.id/kalkulatorzakat, Jenis Zakat = PENGHASILAN | F31: 1. Isi Gaji = nisab per bulan 2. Klik 'Hitung Zakat' | G31: Gaji = 7.640.114 | H31: Boundary | I31: P1 | J31: @regression | K31: Automated | L31: Dinyatakan wajib zakat; zakat = 2,5% x 7.640.114 = 191.002,85 dibulatkan ke atas = Rp 191.003 | M31: Not Run | N31: Pembulatan ke atas (Math.ceil) sesuai kode kalkulator | O31: cypress/e2e/kalkulator-zakat.cy.ts | P31: Fase 1
A32: TC-CALC-006 | B32: TS-CALC-01 | C32: CALC | D32: Boundary: penghasilan 1 rupiah di bawah nisab | E32: Buka https://baznas.go.id/kalkulatorzakat, Jenis Zakat = PENGHASILAN | F32: 1. Isi Gaji = nisab per bulan - 1 2. Klik 'Hitung Zakat' | G32: Gaji = 7.640.113 | H32: Boundary | I32: P1 | J32: @regression | K32: Automated | L32: Pesan belum mencapai nisab tampil | M32: Not Run | O32: cypress/e2e/kalkulator-zakat.cy.ts | P32: Fase 1
A33: TC-CALC-007 | B33: TS-CALC-01 | C33: CALC | D33: Gabungan gaji + lain-lain melewati nisab | E33: Buka https://baznas.go.id/kalkulatorzakat, Jenis Zakat = PENGHASILAN | F33: 1. Isi Gaji & Lain-lain 2. Klik 'Hitung Zakat' | G33: Gaji = 6.000.000 Lain-lain = 2.000.000 | H33: Positive | I33: P1 | J33: @regression | K33: Automated | L33: Jumlah 8.000.000; zakat = Rp 200.000 | M33: Not Run | O33: cypress/e2e/kalkulator-zakat.cy.ts | P33: Fase 1
A34: TC-CALC-008 | B34: TS-CALC-01 | C34: CALC | D34: Nominal besar diformat dan dihitung dengan benar | E34: Buka https://baznas.go.id/kalkulatorzakat, Jenis Zakat = PENGHASILAN | F34: 1. Isi Gaji nominal besar 2. Klik 'Hitung Zakat' | G34: Gaji = 1.000.000.000 | H34: Boundary | I34: P2 | J34: @regression | K34: Automated | L34: Zakat = Rp 25.000.000, format ribuan benar, tidak ada notasi eksponen | M34: Not Run | O34: cypress/e2e/kalkulator-zakat.cy.ts | P34: Fase 2
A35: TC-CALC-009 | B35: TS-CALC-02 | C35: CALC | D35: Input huruf ditolak | E35: Buka https://baznas.go.id/kalkulatorzakat, Jenis Zakat = PENGHASILAN | F35: 1. Ketik huruf pada field Gaji | G35: Gaji = 'abc' | H35: Negative | I35: P1 | J35: @regression | K35: Automated | L35: Field tidak menerima huruf (tetap kosong/angka saja) | M35: Not Run | N35: Terverifikasi: huruf tidak diterima | O35: cypress/e2e/kalkulator-zakat.cy.ts | P35: Fase 1
A36: TC-CALC-010 | B36: TS-CALC-02 | C36: CALC | D36: Input karakter spesial & minus ditolak | E36: Buka https://baznas.go.id/kalkulatorzakat, Jenis Zakat = PENGHASILAN | F36: 1. Ketik karakter spesial pada field Gaji | G36: '-5000000', '1,5', '@#$' | H36: Negative | I36: P2 | J36: @regression | K36: Automated | L36: Hanya digit yang diterima; tidak ada nilai negatif | M36: Not Run | O36: cypress/e2e/kalkulator-zakat.cy.ts | P36: Fase 2
A37: TC-CALC-011 | B37: TS-CALC-02 | C37: CALC | D37: Hitung dengan field kosong / nol | E37: Buka https://baznas.go.id/kalkulatorzakat, Jenis Zakat = PENGHASILAN | F37: 1. Kosongkan Gaji & Lain-lain 2. Klik 'Hitung Zakat' | G37: Gaji = 0 | H37: Negative | I37: P2 | J37: @regression | K37: Automated | L37: Tidak ada error JS; tampil pesan belum mencapai nisab atau validasi wajib isi | M37: Not Run | O37: cypress/e2e/kalkulator-zakat.cy.ts | P37: Fase 2
A38: TC-CALC-012 | B38: TS-CALC-02 | C38: CALC | D38: Field hasil tidak dapat diedit pengguna | E38: Buka https://baznas.go.id/kalkulatorzakat, Jenis Zakat = PENGHASILAN | F38: 1. Coba ketik pada field Nisab & Jumlah Wajib Zakat | G38: - | H38: Negative | I38: P2 | J38: @regression | K38: Automated | L38: Field nisab read-only; field hasil zakat tidak bisa diubah manual | M38: Not Run | O38: cypress/e2e/kalkulator-zakat.cy.ts | P38: Fase 2
A39: TC-CALC-013 | B39: TS-CALC-03 | C39: CALC | D39: Tombol Reset mengosongkan semua input & hasil | E39: Buka https://baznas.go.id/kalkulatorzakat, Jenis Zakat = PENGHASILAN | F39: 1. Isi Gaji 10.000.000, klik Hitung 2. Klik 'Reset' | G39: - | H39: Positive | I39: P1 | J39: @regression | K39: Automated | L39: Semua input & hasil kembali 0; tombol kembali 'Hitung Zakat'; pesan nisab hilang | M39: Not Run | O39: cypress/e2e/kalkulator-zakat.cy.ts | P39: Fase 1
A40: TC-CALC-014 | B40: TS-CALC-03 | C40: CALC | D40: Hasil diperbarui saat input diubah setelah Hitung | E40: Buka https://baznas.go.id/kalkulatorzakat, Jenis Zakat = PENGHASILAN | F40: 1. Isi Gaji 10.000.000, klik Hitung (zakat 250.000) 2. Ubah Gaji jadi 5.000.000 | G40: - | H40: Negative | I40: P1 | J40: @regression @known-bug | K40: Automated | L40: Hasil zakat ikut diperbarui / di-reset, ATAU tombol kembali menjadi 'Hitung Zakat'. Nominal lama tidak boleh dibawa ke pembayaran | M40: Not Run | N40: @known-bug – temuan F-01 (hasil lama tetap 250.000) | O40: cypress/e2e/kalkulator-zakat.cy.ts | P40: Fase 1
...

Sheet Temuan Eksplorasi
A1: ID | B1: Modul | C1: Halaman | D1: Observasi | E1: Seharusnya | F1: Severity | G1: Kategori | H1: Status Verifikasi | I1: Catatan
A2: F-01 | B2: Kalkulator Zakat | C2: /kalkulatorzakat | D2: Setelah klik 'Hitung Zakat' (gaji 10.000.000 -> zakat 250.000), tombol berubah menjadi 'Bayar Zakat'. Saat gaji diubah ke 5.000.000, hasil tetap 250.000 dan tidak dihitung ulang. | E2: Hasil diperbarui atau tombol kembali ke 'Hitung Zakat' saat input berubah. | F2: Medium | G2: Fungsional | H2: Terkonfirmasi saat eksplorasi | I2: TC terkait: Hasil diperbarui saat input diubah setelah Hitung
A3: F-02 | B3: Konfirmasi ZIS | C3: /konfirmasi-zis | D3: Heading halaman tertulis 'INFOMASI UNTUK MUZAKI' (kurang huruf R). | E3: 'INFORMASI UNTUK MUZAKI' | F3: Low | G3: Konten / Typo | H3: Terkonfirmasi
A4: F-03 | B4: Form Jemput Zakat | C4: /form-jemput-zakat | D4: Title halaman 'Tentang Zakat, Jenis Zakat dan Asnaf Penerima Zakat' (sama dengan /zakat). | E4: Title sesuai halaman, mis. 'Form Jemput Zakat | BAZNAS' | F4: Low | G4: SEO | H4: Terkonfirmasi
A5: F-04 | B5: Form Bayar Zakat | C5: bayarzakat.baznas.go.id | D5: Jenis Dana 'Infak' menampilkan sub-jenis berlabel 'Sedekah ...' (Sedekah Palestina, Sedekah Dunia Islam, dll.). | E5: Perlu konfirmasi ke tim bisnis apakah pengelompokan ini sesuai. | F5: Low | G5: Konten | H5: Perlu konfirmasi
A6: F-05 | B6: Form Bayar Zakat | C6: bayarzakat.baznas.go.id | D6: Nominal Rp 65.000 hasil pilihan Fidyah tetap terisi setelah Jenis Dana diganti ke Infak/Sedekah. | E6: Nominal di-reset saat jenis dana berganti. | F6: Low | G6: Fungsional | H6: Terkonfirmasi (perlu cek ulang apakah field kembali editable)
A7: F-06 | B7: Multi-bahasa | C7: Semua halaman | D7: Memilih 'English' pada dropdown bahasa tidak mengubah konten; dropdown kembali ke 'Indonesia'. | E7: Konten diterjemahkan ke Bahasa Inggris. | F7: Medium | G7: Fungsional | H7: Perlu verifikasi ulang di browser lain (menggunakan Google Translate widget)
A8: F-07 | B8: Bottom Navigation | C8: Semua halaman | D8: Label quick menu tertulis 'Layanan Mustahk'. | E8: 'Layanan Mustahik' | F8: Low | G8: Konten / Typo | H8: Terkonfirmasi
A9: F-08 | B9: Homepage | C9: / | D9: Banner 'Sedekah Ramadhan untuk Palestina' masih tampil di slider pada bulan Oktober. | E9: Konten musiman diperbarui sesuai periode. | F9: Low | G9: Konten | H9: Observasi
A10: F-09 | B10: Form Jemput Zakat | C10: /form-jemput-zakat | D10: Field tanggal penjemputan tidak memiliki batas minimum (atribut min), sehingga tanggal lampau berpotensi dapat dipilih. | E10: Tanggal lampau tidak dapat dipilih / ditolak. | F10: Low | G10: Validasi | H10: Perlu verifikasi (validasi JS saat submit belum diuji)
A11: F-10 | B11: Program | C11: /program/kesehatan | D11: Title halaman 'Programkesehatan | BAZNAS' (tanpa spasi, slug mentah). | E11: 'Program Kesehatan | BAZNAS' | F11: Low | G11: SEO | H11: Terkonfirmasi | I11: Kemungkinan berlaku untuk seluruh /program/*
A12: F-11 | B12: Error Handling | C12: /halaman-tidak-ada-xyz | D12: Halaman 404 tidak memiliki title. | E12: Title informatif, mis. 'Halaman Tidak Ditemukan | BAZNAS' | F12: Low | G12: SEO / UX | H12: Terkonfirmasi
A13: F-12 | B13: Kalkulator Zakat -> Bayar Zakat | C13: /kalkulatorzakat | D13: Tombol 'Bayar Zakat' setelah hitung mengarah ke /bayarzakat?jenis=profesi&...&jumlah=250.000, tetapi parameter hilang saat redirect ke bayarzakat.baznas.go.id: sub-jenis kembali 'Zakat Mal' dan nominal kosong. | E13: Jenis dana & nominal hasil kalkulator terisi otomatis di form pembayaran. | F13: Medium | G13: Fungsional | H13: Terkonfirmasi | I13: TC-CALC-015b (@known-bug)
A14: F-13 | B14: Form Bayar Zakat | C14: bayarzakat.baznas.go.id | D14: Pesan validasi email tertulis '...untuk engiriman bukti bayar' (kurang huruf p). | E14: '...untuk pengiriman bukti bayar' | F14: Low | G14: Konten / Typo | H14: Terkonfirmasi (dari konfigurasi validasi halaman)
A15: F-14 | B15: Form Bayar Zakat | C15: bayarzakat.baznas.go.id | D15: Dengan nominal terisi dan nama, HP, email kosong, klik 'Pilih Pembayaran' langsung lanjut ke halaman Metode Pembayaran dan memanggil endpoint data muzaki. Aturan validasi (nama, HP min. 8 digit, email) ada di halaman tetapi tidak dijalankan pada langkah ini. | E15: Pesan validasi tampil dan tidak lanjut sebelum data muzaki valid. | F15: Medium | G15: Validasi | H15: Terkonfirmasi untuk field kosong (request ke server diblokir saat eksplorasi) | I15: TC-PAY-012..014 (@known-bug)
A16: F-15 | B16: Form Jemput Zakat | C16: /form-jemput-zakat | D16: Tidak ditemukan validasi nominal minimum Rp1.000.000 di sisi klien (tanpa atribut min/pattern; handler submit hanya memeriksa captcha). | E16: Nominal di bawah Rp1.000.000 ditolak sebelum dikirim. | F16: Low | G16: Validasi | H16: Perlu konfirmasi validasi di sisi server | I16: TC-JMP-007 (@known-bug)
A17: F-16 | B17: Kalkulator Zakat | C17: /kalkulatorzakat | D17: Field 'Jumlah penghasilan per bulan' dapat diedit manual, padahal merupakan hasil penjumlahan otomatis. | E17: Field hasil penjumlahan bersifat read-only. | F17: Low | G17: Fungsional / UX | H17: Terkonfirmasi
